<?xml version="1.0" ?>
<sdf version="1.6">

    <model name="conveyor_belt">

        <model name="conveyorbelt_fixed">

            <static>true</static>

            <link name="belt_visual">
                <visual name="visual">
                    <geometry>
                        <mesh>
                            <scale>1 1 1</scale>
                            <uri>model://conveyor_belt/meshes/conveyor_belt.dae</uri>
                        </mesh>
                    </geometry>
                </visual>
                <collision name="collision">
                    <origin xyz="0.0 0.0 0" rpy="0.0 0.0 0.0"/>
                    <geometry>
                        <mesh>
                            <scale>1 1 1</scale>
                            <uri>model://conveyor_belt/meshes/conveyor_belt.dae</uri>
                        </mesh>
                    </geometry>
                </collision>
            </link>

        </model>

        <model name="conveyorbelt_moving">

            <allow_auto_disable>0</allow_auto_disable>
            <static>false</static>

            <pose>0 0 0.75 0 0 0.0</pose>

            <link name="belt_moving">
                <inertial>
                    <mass>100.0</mass>
                    <inertia>
                        <ixx>0.0</ixx>
                        <ixy>0.0</ixy>
                        <ixz>0.0</ixz>
                        <iyy>0.0</iyy>
                        <iyz>0.0</iyz>
                        <izz>0.0</izz>
                    </inertia>
                </inertial>
                <collision name="belt_collision">
                    <geometry>
                        <box>
                            <size>0.425 1.2 0.001</size>
                        </box>
                    </geometry>
                </collision>
            </link>

        </model>

        <joint name="belt_joint" type="prismatic">
            <parent>conveyorbelt_fixed::belt_visual</parent>
            <child>conveyorbelt_moving::belt_moving</child>
            <axis>
                <xyz>0 1 0</xyz>
                <limit>
                    <lower>0.0</lower>
                    <upper>1.0</upper>
                </limit>
            </axis>
        </joint>

        <gazebo>
            <plugin filename="libROS2ConveyorBeltPlugin.so" name="ros2_conveyorbelt_plugin">
                <ros>
                    <namespace></namespace>
                </ros>
                <max_velocity>0.2</max_velocity>
                <publish_rate>10</publish_rate>
            </plugin>
        </gazebo>

    </model>

</sdf>